<?xml version="1.0"?>
<robot xmlns:xacro="http://www.ros.org/wiki/xacro">

    <xacro:macro name="left_leg_link_xacro">

        <link name="left_thigh_link">

            <visual>
                <origin xyz="0.0 0.0 -0.15" rpy="0.0 0.0 0.0"/>
                <geometry>
                    <box size="0.025 0.02 0.3"/>
                </geometry>
                <material name="white">
                    <color rgba="1.0 1.0 1.0 1.0"/>
                </material>
            </visual>

        </link>

        <joint name="left_thigh_link_joint" type="continuous">
            <origin xyz="0.0 -0.16 -0.07" rpy="0.0 0.0 0.0"/>
            <parent link="base_link"/>
            <child link="left_thigh_link"/>
            <axis xyz="0.0 1.0 0.0"/>
        </joint>

    </xacro:macro>
    
</robot>
