<?xml version="1.0"?>
<robot xmlns:xacro="http://www.ros.org/wiki/xacro">
<xacro:include filename="$(find robot_description_pkg)/urdf/common_inertia.xacro"/>
    <xacro:macro name="wheel_link_xacro" params="position xyz">
        <link name="${position}_wheel_link">

            <visual>
                <origin xyz="0.0 0.0 0.0" rpy="1.57079 0.0 0.0"/>
                <geometry>
                    <cylinder radius="0.1" length="0.03"/>
                </geometry>
                <material name="black">
                    <color rgba="0.0 0.0 0.0 1.0"/>
                </material>
            </visual>

            <collision>
                <origin xyz="0.0 0.0 0.0" rpy="1.57079 0.0 0.0"/>
                <geometry>
                    <cylinder radius="0.1" length="0.03"/>
                </geometry>
                <material name="black">
                    <color rgba="0.0 0.0 0.0 1.0"/>
                </material>
            </collision>

            <xacro:cylinder_inertia_y m="1.18" r="0.1" h="0.03" xyz="0.0 0.0 0.0" rpy="0.0 0.0 0.0"/>

        </link>

        <joint name="${position}_wheel_joint" type="continuous">
            <origin xyz="${xyz}" rpy="0.0 0.0 0.0"/>
            <parent link="${position}_shank_link"/>
            <child link="${position}_wheel_link"/>
            <axis xyz="0.0 1.0 0.0"/>
        </joint>

         <gazebo reference="${position}_wheel_link">
	        <material>Gazebo/Yellow</material>
	        <mu1 value="20.0"/>
	        <mu2 value="20.0"/>
	        <kp value="1000000000000000.0"/>
	        <kd value="1.0"/>
        </gazebo>

    </xacro:macro>
   
</robot>